Workbook

Sheet Data_Karyawan
A1: NIK | B1: Nama | C1: Jabatan | D1: Gaji Pokok | E1: Tunjangan | F1: Status PTKP
A2: 3271062612000018 | B2: Dylan Eldiyano Ramadhan | C2: Analyst | D2: 18000000 | E2: 220000 | F2: TK/0
A3: 3402122812860002 | B3: Berlianagara A. H | C3: Analyst | D3: 6000000 | E3: 220000 | F3: K/3
A4: 0000000000000000 | B4: Zwin | C4: Analyst | D4: 5730000 | E4: 220000
A5: 3578105610980006 | B5: Nabilla Firdaus Palesta Lihawa | C5: Finance | D5: 7000000 | E5: 220000 | F5: TK/0
A6: 3509066607020002 | B6: Fiagem Dwi Woro Bahwani | C6: Personal Assitant | D6: 5000000 | E6: 220000 | F6: TK/0
A7: 3516132404020001 | B7: Alfian Dwi Nugraha | C7: IT/Programmer | D7: 7000000 | E7: 220000 | F7: TK/0
A8: 3506251905960002 | B8: Masrukin | C8: Media | D8: 7000000 | E8: 220000 | F8: TK/0
A9: 3509031207020013 | B9: Bowo Prayoga | C9: Media | D9: 4500000 | E9: 220000 | F9: TK/0
A10: 1802180809010001 | B10: Satria Baladewa Harahap | C10: Media | D10: 5000000 | E10: 220000 | F10: TK/0
A11: 3515182611990006 | B11: Rudi Ardi Hamzah | C11: Media | D11: 4000000 | E11: 220000 | F11: TK/0
A12: 3505101808040002 | B12: Muhammad Fariza Agustino | C12: Media | D12: 5000000 | E12: 220000 | F12: TK/0
A13: 0000000000000001 | B13: Pendik | C13: Media | D13: 2500000 | E13: 220000
A14: 3523037103030001 | B14: Meysa Mahfudhoh | C14: Media | D14: 3500000 | E14: 220000
A15: 3515153107010001 | B15: M. Rizqi R. | C15: Media | D15: 2500000 | E15: 220000 | F15: TK/0
A16: 6201026602010003 | B16: Florencia Irena | C16: Marketing - Visual Design | D16: 5000000 | E16: 220000 | F16: TK/0
A17: 3509050202010002 | B17: Fahrul Muttaqin | C17: Marketing - Visual Design | D17: 4500000 | E17: 220000 | F17: TK/0
A18: 3578030810010002 | B18: Abid Ariq Athallah | C18: Marketing - Visual Design | D18: 4000000 | E18: 220000 | F18: TK/0
A19: 3578012501030002 | B19: Bambang Adi | C19: Marketing - Visual Design | D19: 3230000 | E19: 220000
A20: 3522082502850005 | B20: Mochamad Soleh | C20: Operasional | D20: 4500000 | E20: 220000 | F20: K/2
A21: 3524013107840001 | B21: Kamit | C21: Operasional | D21: 3500000 | E21: 220000 | F21: K/1
A22: 3522081109070003 | B22: Galang Belvasya Septian | C22: Operasional | D22: 3000000 | E22: 220000 | F22: TK/0

Sheet Payroll_Februari_2026
J1: DITANGGUNG PERUSAHAAN | N1: POTONGAN KARYAWAN | O1: POTONGAN KARYAWAN
D2: 5288796 | E2: =D2*5% -> 264439.8 | J2: 0.04 | K2: 3.7% | L2: 0.24% | M2: 0.3% | N2: 0.01 | O2: 0.02
H3: 19 | T3: 25000
A4: NIK | B4: NAMA | C4: SALARY | D4: RATE BPJS KES | E4: RATE BPJS TK | F4: RATE PAJAK | G4: GROSS | H4: HARI KERJA | I4: TOTAL GROSS BULAN BERJALAN | J4: KESEHATAN | K4: JHT | L4: JKK | M4: JKM | N4: BPJS KES | O4: BPJSTK - JHT | P4: PPH 21 | Q4: TOTAL POTONGAN PPH 21, BPJS TK & KES | R4: TOTAL POTONGAN INTERNAL | S4: UANG TRANSPORT | T4: UANG MAKAN | U4: TOTAL TUNJANGAN | V4: TOTAL BONUS | W4: TAKE HOME PAY
A5: 3271062612000018 | B5: =VLOOKUP(A5,Data_Karyawan!A:F,2,FALSE()) -> Dylan Eldiyano Ramadhan | C5: =VLOOKUP(A5,Data_Karyawan!A:F,4,FALSE()) -> 18000000 | D5: 5288796 | E5: 5000000 | F5: 10412000 | G5: =C5 -> 18000000 | H5: 19 | I5: =G5 -> 18000000 | J5: =D5*$J$2 -> 211551.84 | K5: =E5*$K$2 -> 185000 | L5: =E5*$L$2 -> 12000 | M5: =E5*$M$2 -> 15000 | N5: =-D5*$N$2 -> -52887.96 | O5: =-E5*$O$2 -> -100000 | P5: -260300 | Q5: =SUM(N5:P5) -> -413187.96 | S5: =VLOOKUP(A5,Data_Karyawan!A:F,5,FALSE()) -> 220000 | T5: 0 | U5: =S5+T5 -> 220000 | W5: =I5+Q5+R5+U5+V5 -> 17806812
A6: 3402122812860002 | B6: =VLOOKUP(A6,Data_Karyawan!A:F,2,FALSE()) -> Berlianagara A. H | C6: 6000000 | D6: 5288796 | E6: 5000000 | G6: =C6 -> 6000000 | H6: 19 | I6: =G6 -> 6000000 | J6: =D6*$J$2 -> 211551.84 | K6: =E6*$K$2 -> 185000 | L6: =E6*$L$2 -> 12000 | M6: =E6*$M$2 -> 15000 | N6: =-D6*$N$2 -> -52887.96 | O6: =-E6*$O$2 -> -100000 | Q6: =SUM(N6:P6) -> -152887.96 | S6: 220000 | T6: =H6*$T$3 -> 475000 | U6: =S6+T6 -> 695000 | W6: =I6+Q6+R6+U6+V6 -> 6542112
A7: 0000000000000000 | B7: =VLOOKUP(A7,Data_Karyawan!A:F,2,FALSE()) -> Zwin | C7: 5730000 | D7: 0 | E7: 0 | G7: =C7 -> 5730000 | H7: =19-5 -> 14 | I7: =H7/H3*G7 -> 4222105.3 | J7: =D7*$J$2 -> 0 | K7: =E7*$K$2 -> 0 | L7: =E7*$L$2 -> 0 | M7: =E7*$M$2 -> 0 | N7: =-D7*$N$2 -> 0 | O7: =-E7*$O$2 -> 0 | Q7: =SUM(N7:P7) -> 0 | S7: 220000 | T7: =H7*$T$3 -> 350000 | U7: =S7+T7 -> 570000 | W7: =I7+Q7+R7+U7+V7 -> 4792105.3
A8: 3578105610980006 | B8: =VLOOKUP(A8,Data_Karyawan!A:F,2,FALSE()) -> Nabilla Firdaus Palesta Lihawa | C8: 7000000 | D8: 5288796 | E8: 5000000 | G8: =C8 -> 7000000 | H8: 19 | I8: =G8 -> 7000000 | J8: =D8*$J$2 -> 211551.84 | K8: =E8*$K$2 -> 185000 | L8: =E8*$L$2 -> 12000 | M8: =E8*$M$2 -> 15000 | N8: =-D8*$N$2 -> -52887.96 | O8: =-E8*$O$2 -> -100000 | Q8: =SUM(N8:P8) -> -152887.96 | S8: 220000 | T8: =H8*$T$3 -> 475000 | U8: =S8+T8 -> 695000 | W8: =I8+Q8+R8+U8+V8 -> 7542112
A9: 3509066607020002 | B9: =VLOOKUP(A9,Data_Karyawan!A:F,2,FALSE()) -> Fiagem Dwi Woro Bahwani | C9: 5000000 | D9: 0 | E9: 0 | G9: =C9 -> 5000000 | H9: 19 | I9: =G9 -> 5000000 | J9: =D9*$J$2 -> 0 | K9: =E9*$K$2 -> 0 | L9: =E9*$L$2 -> 0 | M9: =E9*$M$2 -> 0 | N9: =-D9*$N$2 -> 0 | O9: =-E9*$O$2 -> 0 | Q9: =SUM(N9:P9) -> 0 | S9: 220000 | T9: =H9*$T$3 -> 475000 | U9: =S9+T9 -> 695000 | W9: =I9+Q9+R9+U9+V9 -> 5695000
A10: 3516132404020001 | B10: =VLOOKUP(A10,Data_Karyawan!A:F,2,FALSE()) -> Alfian Dwi Nugraha | C10: 7000000 | D10: 5288796 | E10: 5000000 | G10: =C10 -> 7000000 | H10: 19 | I10: =G10 -> 7000000 | J10: =D10*$J$2 -> 211551.84 | K10: =E10*$K$2 -> 185000 | L10: =E10*$L$2 -> 12000 | M10: =E10*$M$2 -> 15000 | N10: =-D10*$N$2 -> -52887.96 | O10: =-E10*$O$2 -> -100000 | Q10: =SUM(N10:P10) -> -152887.96 | S10: 220000 | T10: =H10*$T$3 -> 475000 | U10: =S10+T10 -> 695000 | V10: 5000000 | W10: =I10+Q10+R10+U10+V10 -> 12542112
A11: 3506251905960002 | B11: =VLOOKUP(A11,Data_Karyawan!A:F,2,FALSE()) -> Masrukin | C11: 7000000 | D11: 5288796 | E11: 5000000 | G11: =C11 -> 7000000 | H11: 19 | I11: =G11 -> 7000000 | J11: =D11*$J$2 -> 211551.84 | K11: =E11*$K$2 -> 185000 | L11: =E11*$L$2 -> 12000 | M11: =E11*$M$2 -> 15000 | N11: =-D11*$N$2 -> -52887.96 | O11: =-E11*$O$2 -> -100000 | Q11: =SUM(N11:P11) -> -152887.96 | S11: 220000 | T11: =H11*$T$3 -> 475000 | U11: =S11+T11 -> 695000 | W11: =I11+Q11+R11+U11+V11 -> 7542112
A12: 3509031207020013 | B12: =VLOOKUP(A12,Data_Karyawan!A:F,2,FALSE()) -> Bowo Prayoga | C12: 5000000 | D12: 5288796 | E12: 5000000 | G12: =C12 -> 5000000 | H12: 19 | I12: =G12 -> 5000000 | J12: =D12*$J$2 -> 211551.84 | K12: =E12*$K$2 -> 185000 | L12: =E12*$L$2 -> 12000 | M12: =E12*$M$2 -> 15000 | N12: =-D12*$N$2 -> -52887.96 | O12: =-E12*$O$2 -> -100000 | Q12: =SUM(N12:P12) -> -152887.96 | S12: 220000 | T12: =H12*$T$3 -> 475000 | U12: =S12+T12 -> 695000 | W12: =I12+Q12+R12+U12+V12 -> 5542112
A13: 1802180809010001 | B13: =VLOOKUP(A13,Data_Karyawan!A:F,2,FALSE()) -> Satria Baladewa Harahap | C13: 5000000 | D13: 5288796 | E13: 5000000 | G13: =C13 -> 5000000 | H13: 19 | I13: =G13 -> 5000000 | J13: =D13*$J$2 -> 211551.84 | K13: =E13*$K$2 -> 185000 | L13: =E13*$L$2 -> 12000 | M13: =E13*$M$2 -> 15000 | N13: =-D13*$N$2 -> -52887.96 | O13: =-E13*$O$2 -> -100000 | Q13: =SUM(N13:P13) -> -152887.96 | S13: 220000 | T13: =H13*$T$3 -> 475000 | U13: =S13+T13 -> 695000 | W13: =I13+Q13+R13+U13+V13 -> 5542112
A14: 3515182611990006 | B14: =VLOOKUP(A14,Data_Karyawan!A:F,2,FALSE()) -> Rudi Ardi Hamzah | C14: 4000000 | D14: 0 | E14: 0 | G14: =C14 -> 4000000 | H14: 19 | I14: =G14 -> 4000000 | J14: =D14*$J$2 -> 0 | K14: =E14*$K$2 -> 0 | L14: =E14*$L$2 -> 0 | M14: =E14*$M$2 -> 0 | N14: =-D14*$N$2 -> 0 | O14: =-E14*$O$2 -> 0 | Q14: =SUM(N14:P14) -> 0 | S14: 220000 | T14: =H14*$T$3 -> 475000 | U14: =S14+T14 -> 695000 | W14: =I14+Q14+R14+U14+V14 -> 4695000
A15: 3505101808040002 | B15: =VLOOKUP(A15,Data_Karyawan!A:F,2,FALSE()) -> Muhammad Fariza Agustino | C15: 5000000 | D15: 5288796 | E15: 5000000 | G15: =C15 -> 5000000 | H15: 19 | I15: =G15 -> 5000000 | J15: =D15*$J$2 -> 211551.84 | K15: =E15*$K$2 -> 185000 | L15: =E15*$L$2 -> 12000 | M15: =E15*$M$2 -> 15000 | N15: =-D15*$N$2 -> -52887.96 | O15: =-E15*$O$2 -> -100000 | Q15: =SUM(N15:P15) -> -152887.96 | S15: 220000 | T15: =H15*$T$3 -> 475000 | U15: =S15+T15 -> 695000 | W15: =I15+Q15+R15+U15+V15 -> 5542112
A16: 0000000000000001 | B16: =VLOOKUP(A16,Data_Karyawan!A:F,2,FALSE()) -> Pendik | C16: 2500000 | D16: 0 | E16: 0 | G16: =C16 -> 2500000 | H16: 19 | I16: =G16 -> 2500000 | J16: =D16*$J$2 -> 0 | K16: =E16*$K$2 -> 0 | L16: =E16*$L$2 -> 0 | M16: =E16*$M$2 -> 0 | N16: =-D16*$N$2 -> 0 | O16: =-E16*$O$2 -> 0 | Q16: =SUM(N16:P16) -> 0 | S16: 0 | U16: =S16+T16 -> 0 | W16: =I16+Q16+R16+U16+V16 -> 2500000
A17: 3523037103030001 | B17: =VLOOKUP(A17,Data_Karyawan!A:F,2,FALSE()) -> Meysa Mahfudhoh | C17: 3500000 | D17: 0 | E17: 0 | G17: =C17 -> 3500000 | H17: 17 | I17: =H17/H3*G17 -> 3131578.9 | J17: =D17*$J$2 -> 0 | K17: =E17*$K$2 -> 0 | L17: =E17*$L$2 -> 0 | M17: =E17*$M$2 -> 0 | N17: =-D17*$N$2 -> 0 | O17: =-E17*$O$2 -> 0 | Q17: =SUM(N17:P17) -> 0 | S17: 220000 | T17: =H17*$T$3 -> 425000 | U17: =S17+T17 -> 645000 | W17: =I17+Q17+R17+U17+V17 -> 3776578.9
A18: 3515153107010001 | B18: =VLOOKUP(A18,Data_Karyawan!A:F,2,FALSE()) -> M. Rizqi R. | C18: 2500000 | D18: 0 | E18: 0 | G18: =C18 -> 2500000 | H18: 19 | I18: =G18 -> 2500000 | J18: =D18*$J$2 -> 0 | K18: =E18*$K$2 -> 0 | L18: =E18*$L$2 -> 0 | M18: =E18*$M$2 -> 0 | N18: =-D18*$N$2 -> 0 | O18: =-E18*$O$2 -> 0 | Q18: =SUM(N18:P18) -> 0 | S18: 0 | U18: =S18+T18 -> 0 | W18: =I18+Q18+R18+U18+V18 -> 2500000
A19: 6201026602010003 | B19: =VLOOKUP(A19,Data_Karyawan!A:F,2,FALSE()) -> Florencia Irena | C19: 5000000 | D19: 5288796 | E19: 5000000 | G19: =C19 -> 5000000 | H19: 7 | I19: =H19/H3*G19 -> 1842105.3 | J19: =D19*$J$2 -> 211551.84 | K19: =E19*$K$2 -> 185000 | L19: =E19*$L$2 -> 12000 | M19: =E19*$M$2 -> 15000 | N19: =-D19*$N$2 -> -52887.96 | O19: =-E19*$O$2 -> -100000 | Q19: =SUM(N19:P19) -> -152887.96 | S19: 220000 | T19: =H19*$T$3 -> 175000 | U19: =S19+T19 -> 395000 | W19: =I19+Q19+R19+U19+V19 -> 2084217.3
A20: 3509050202010002 | B20: =VLOOKUP(A20,Data_Karyawan!A:F,2,FALSE()) -> Fahrul Muttaqin | C20: 4500000 | D20: 5288796 | E20: 4500000 | G20: =C20 -> 4500000 | H20: 19 | I20: =G20 -> 4500000 | J20: =D20*$J$2 -> 211551.84 | K20: =E20*$K$2 -> 166500 | L20: =E20*$L$2 -> 10800 | M20: =E20*$M$2 -> 13500 | N20: =-D20*$N$2 -> -52887.96 | O20: =-E20*$O$2 -> -90000 | Q20: =SUM(N20:P20) -> -142887.96 | S20: 220000 | T20: =H20*$T$3 -> 475000 | U20: =S20+T20 -> 695000 | W20: =I20+Q20+R20+U20+V20 -> 5052112
A21: 3578030810010002 | B21: =VLOOKUP(A21,Data_Karyawan!A:F,2,FALSE()) -> Abid Ariq Athallah | C21: 4000000 | D21: 5288796 | E21: 4000000 | G21: =C21 -> 4000000 | H21: 19 | I21: =G21 -> 4000000 | J21: =D21*$J$2 -> 211551.84 | K21: =E21*$K$2 -> 148000 | L21: =E21*$L$2 -> 9600 | M21: =E21*$M$2 -> 12000 | N21: =-D21*$N$2 -> -52887.96 | O21: =-E21*$O$2 -> -80000 | Q21: =SUM(N21:P21) -> -132887.96 | S21: 220000 | T21: =H21*$T$3 -> 475000 | U21: =S21+T21 -> 695000 | W21: =I21+Q21+R21+U21+V21 -> 4562112
A22: 3578012501030002 | B22: =VLOOKUP(A22,Data_Karyawan!A:F,2,FALSE()) -> Bambang Adi | C22: 3230000 | D22: 0 | E22: 0 | G22: =C22 -> 3230000 | H22: 10 | I22: =H22/H3*G22 -> 1700000 | J22: =D22*$J$2 -> 0 | K22: =E22*$K$2 -> 0 | L22: =E22*$L$2 -> 0 | M22: =E22*$M$2 -> 0 | N22: =-D22*$N$2 -> 0 | O22: =-E22*$O$2 -> 0 | Q22: =SUM(N22:P22) -> 0 | S22: 220000 | T22: =H22*$T$3 -> 250000 | U22: =S22+T22 -> 470000 | W22: =I22+Q22+R22+U22+V22 -> 2170000
A23: 3522082502850005 | B23: =VLOOKUP(A23,Data_Karyawan!A:F,2,FALSE()) -> Mochamad Soleh | C23: 4500000 | D23: 5288796 | E23: 4500000 | G23: =C23 -> 4500000 | H23: 19 | I23: =G23 -> 4500000 | J23: =D23*$J$2 -> 211551.84 | K23: =E23*$K$2 -> 166500 | L23: =E23*$L$2 -> 10800 | M23: =E23*$M$2 -> 13500 | N23: =-D23*$N$2 -> -52887.96 | O23: =-E23*$O$2 -> -90000 | Q23: =SUM(N23:P23) -> -142887.96 | S23: 220000 | T23: =H23*$T$3 -> 475000 | U23: =S23+T23 -> 695000 | W23: =I23+Q23+R23+U23+V23 -> 5052112
A24: 3524013107840001 | B24: =VLOOKUP(A24,Data_Karyawan!A:F,2,FALSE()) -> Kamit | C24: 3500000 | D24: 5288796 | E24: 3500000 | G24: =C24 -> 3500000 | H24: 19 | I24: =G24 -> 3500000 | J24: =D24*$J$2 -> 211551.84 | K24: =E24*$K$2 -> 129500 | L24: =E24*$L$2 -> 8400 | M24: =E24*$M$2 -> 10500 | N24: =-D24*$N$2 -> -52887.96 | O24: =-E24*$O$2 -> -70000 | Q24: =SUM(N24:P24) -> -122887.96 | R24: -400000 | S24: 220000 | T24: =H24*$T$3 -> 475000 | U24: =S24+T24 -> 695000 | W24: =I24+Q24+R24+U24+V24 -> 3672112
A25: 3522081109070003 | B25: =VLOOKUP(A25,Data_Karyawan!A:F,2,FALSE()) -> Galang Belvasya Septian | C25: 3000000 | D25: 5288796 | G25: =C25 -> 3000000 | H25: 19 | I25: =G25 -> 3000000 | J25: =D25*$J$2 -> 211551.84 | K25: =E25*$K$2 -> 0 | L25: =E25*$L$2 -> 0 | M25: =E25*$M$2 -> 0 | N25: =-D25*$N$2 -> -52887.96 | O25: 0 | Q25: =SUM(N25:P25) -> -52887.96 | S25: 220000 | T25: =H25*$T$3 -> 475000 | U25: =S25+T25 -> 695000 | W25: =I25+Q25+R25+U25+V25 -> 3642112
C26: =SUBTOTAL(9,C5:C25) -> 110960000 | D26: =SUBTOTAL(9,D5:D25) -> 74043144 | E26: =SUBTOTAL(9,E5:E25) -> 61500000 | F26: =SUBTOTAL(9,F5:F25) -> 10412000 | G26: =SUBTOTAL(9,G5:G25) -> 110960000 | J26: =SUBTOTAL(9,J5:J25) -> 2961725.8 | K26: =SUBTOTAL(9,K5:K25) -> 2275500 | L26: =SUBTOTAL(9,L5:L25) -> 147600 | M26: =SUBTOTAL(9,M5:M25) -> 184500 | N26: =SUBTOTAL(9,N5:N25) -> -740431.44 | O26: =SUBTOTAL(9,O5:O25) -> -1230000 | P26: =SUBTOTAL(9,P5:P25) -> -260300 | Q26: =SUBTOTAL(9,Q5:Q25) -> -2230731.4 | ... W26: =SUBTOTAL(9,W5:W25) -> 1.1879506e+08
Q29: Kamit | R29: Pot ke-2 | S29: 4/6

Sheet Slip_Gaji
A1: SLIP GAJI KARYAWAN
A2: Periode: Februari 2026
A3: NIK | B3: =Payroll_Februari_2026!A5 -> 3271062612000018 | D3: Jabatan | E3: =VLOOKUP(Payroll_Februari_2026!A5,Data_Karyawan!A:F,3,FALSE()) -> Analyst
A4: Nama | B4: =Payroll_Februari_2026!B5 -> Dylan Eldiyano Ramadhan | D4: Status PTKP | E4: =IFERROR(VLOOKUP(Payroll_Februari_2026!A5,Data_Karyawan!A:F,6,FALSE()),"-") -> TK/0
A5: Hari Kerja | B5: =Payroll_Februari_2026!H5 -> 19
A7: PENDAPATAN | D7: POTONGAN
A8: Gaji Pokok (Prorata) | B8: =Payroll_Februari_2026!I5 -> 18000000 | D8: BPJS Kesehatan | E8: =ABS(Payroll_Februari_2026!N5) -> 52887.96
A9: Uang Transport | B9: =Payroll_Februari_2026!S5 -> 220000 | D9: BPJS TK - JHT | E9: =ABS(Payroll_Februari_2026!O5) -> 100000
A10: Uang Makan | B10: =Payroll_Februari_2026!T5 -> 0 | D10: PPH 21 | E10: =ABS(IF(Payroll_Februari_2026!P5="",0,Payroll_Februari_2026!P5)) -> 260300
A11: Bonus | B11: =IF(Payroll_Februari_2026!V5="",0,Payroll_Februari_2026!V5) -> 0 | D11: Potongan Internal | E11: =ABS(IF(Payroll_Februari_2026!R5="",0,Payroll_Februari_2026!R5)) -> 0
A13: TOTAL PENDAPATAN | B13: =SUM(B8:B11) -> 18220000 | D13: TOTAL POTONGAN | E13: =SUM(E8:E11) -> 413187.96
A15: TAKE HOME PAY | E15: =Payroll_Februari_2026!W5 -> 17806812
A16: =" BPJS Kes (Perusahaan): "&TEXT(Payroll_Februari_2026!J5,"#,##0")&" | JHT: "&TEXT(Payroll_Februari_2026!K5,"#,##0")&" | JKK: "&TEXT(Payroll_Februari_2026!L5,"#,##0")&" | JKM: "&TEXT(Payroll_Februari_2026!M5,"#,##0") -> BPJS Kes (Perusahaan): 211,552 | JHT: 185,000 | JKK: 12,000 | JKM: 15,000
A21: SLIP GAJI KARYAWAN
A22: Periode: Februari 2026
A23: NIK | B23: =Payroll_Februari_2026!A6 -> 3402122812860002 | D23: Jabatan | E23: =VLOOKUP(Payroll_Februari_2026!A6,Data_Karyawan!A:F,3,FALSE()) -> Analyst
A24: Nama | B24: =Payroll_Februari_2026!B6 -> Berlianagara A. H | D24: Status PTKP | E24: =IFERROR(VLOOKUP(Payroll_Februari_2026!A6,Data_Karyawan!A:F,6,FALSE()),"-") -> K/3
A25: Hari Kerja | B25: =Payroll_Februari_2026!H6 -> 19
A27: PENDAPATAN | D27: POTONGAN
A28: Gaji Pokok (Prorata) | B28: =Payroll_Februari_2026!I6 -> 6000000 | D28: BPJS Kesehatan | E28: =ABS(Payroll_Februari_2026!N6) -> 52887.96
A29: Uang Transport | B29: =Payroll_Februari_2026!S6 -> 220000 | D29: BPJS TK - JHT | E29: =ABS(Payroll_Februari_2026!O6) -> 100000
A30: Uang Makan | B30: =Payroll_Februari_2026!T6 -> 475000 | D30: PPH 21 | E30: =ABS(IF(Payroll_Februari_2026!P6="",0,Payroll_Februari_2026!P6)) -> 0
A31: Bonus | B31: =IF(Payroll_Februari_2026!V6="",0,Payroll_Februari_2026!V6) -> 0 | D31: Potongan Internal | E31: =ABS(IF(Payroll_Februari_2026!R6="",0,Payroll_Februari_2026!R6)) -> 0
A33: TOTAL PENDAPATAN | B33: =SUM(B28:B31) -> 6695000 | D33: TOTAL POTONGAN | E33: =SUM(E28:E31) -> 152887.96
A35: TAKE HOME PAY | E35: =Payroll_Februari_2026!W6 -> 6542112
A36: =" BPJS Kes (Perusahaan): "&TEXT(Payroll_Februari_2026!J6,"#,##0")&" | JHT: "&TEXT(Payroll_Februari_2026!K6,"#,##0")&" | JKK: "&TEXT(Payroll_Februari_2026!L6,"#,##0")&" | JKM: "&TEXT(Payroll_Februari_2026!M6,"#,##0") -> BPJS Kes (Perusahaan): 211,552 | JHT: 185,000 | JKK: 12,000 | JKM: 15,000
A41: SLIP GAJI KARYAWAN
A42: Periode: Februari 2026
A43: NIK | B43: =Payroll_Februari_2026!A7 -> 0000000000000000 | D43: Jabatan | E43: =VLOOKUP(Payroll_Februari_2026!A7,Data_Karyawan!A:F,3,FALSE()) -> Analyst
A44: Nama | B44: =Payroll_Februari_2026!B7 -> Zwin | D44: Status PTKP | E44: =IFERROR(VLOOKUP(Payroll_Februari_2026!A7,Data_Karyawan!A:F,6,FALSE()),"-") -> 0
A45: Hari Kerja | B45: =Payroll_Februari_2026!H7 -> 14
A47: PENDAPATAN | D47: POTONGAN
A48: Gaji Pokok (Prorata) | B48: =Payroll_Februari_2026!I7 -> 4222105.3 | D48: BPJS Kesehatan | E48: =ABS(Payroll_Februari_2026!N7) -> 0
A49: Uang Transport | B49: =Payroll_Februari_2026!S7 -> 220000 | D49: BPJS TK - JHT | E49: =ABS(Payroll_Februari_2026!O7) -> 0
A50: Uang Makan | B50: =Payroll_Februari_2026!T7 -> 350000 | D50: PPH 21 | E50: =ABS(IF(Payroll_Februari_2026!P7="",0,Payroll_Februari_2026!P7)) -> 0
A51: Bonus | B51: =IF(Payroll_Februari_2026!V7="",0,Payroll_Februari_2026!V7) -> 0 | D51: Potongan Internal | E51: =ABS(IF(Payroll_Februari_2026!R7="",0,Payroll_Februari_2026!R7)) -> 0
A53: TOTAL PENDAPATAN | B53: =SUM(B48:B51) -> 4792105.3 | D53: TOTAL POTONGAN | E53: =SUM(E48:E51) -> 0
A55: TAKE HOME PAY | E55: =Payroll_Februari_2026!W7 -> 4792105.3
A56: =" BPJS Kes (Perusahaan): "&TEXT(Payroll_Februari_2026!J7,"#,##0")&" | JHT: "&TEXT(Payroll_Februari_2026!K7,"#,##0")&" | JKK: "&TEXT(Payroll_Februari_2026!L7,"#,##0")&" | JKM: "&TEXT(Payroll_Februari_2026!M7,"#,##0") -> BPJS Kes (Perusahaan): 0 | JHT: 0 | JKK: 0 | JKM: 0
A61: SLIP GAJI KARYAWAN
...
